Workbook

Sheet Twój kod jest świetny, a co z T
A1: Submission ID | B1: Submitted at | C1: CZY_PROGRAMISTA | D1: STAŻ PRACY | E1: POLSKA | F1: E_PLUS_1 | G1: U_MINUS_1 | H1: S_MINUS_1 | I1: SE_PLUS_1 | J1: I_PLUS_1 | K1: E_MINUS_2 | L1: U_PLUS_2 | M1: S_PLUS_2 | N1: SE_MINUS_2 | O1: I_MINUS_2 | P1: E_PLUS_3 | Q1: U_MINUS_3 | R1: S_MINUS_3 | S1: SE_PLUS_3 | T1: I_PLUS_3 | U1: E_MINUS_4 | V1: U_PLUS_4 | W1: S_PLUS_4 | X1: SE_MINUS_4 | Y1: I_MINUS_4 | Z1: Forma zatrudnienia | AA1: Zarobki | AC1: U_MINUS_1_REC | AD1: S_MINUS_1_REC | AE1: E_MINUS_2_REC | AF1: SE_MINUS_2_REC | AG1: I_MINUS_2_REC | AH1: U_MINUS_3_REC | AI1: S_MINUS_3_REC | AJ1: E_MINUS_4_REC | AK1: SE_MINUS_4_REC | AL1: I_MINUS_4_REC | AN1: WYNIK_EKSTRAWERSJA | AO1: WYNIK_UGODOWOSC | AP1: WYNIK_SUMIENNOSC | AQ1: WYNIK_STABILNOSC_EMOCJONALNA | AR1: WYNIK_INTELEKT
A2: 9oxqs3ejiynzbyrf5915oz9oxqs2ztbl | B2: 2025-12-23 09:46:52 | C2: Tak | D2: 1 | E2: Tak | F2: 2 | G2: 4 | H2: 1 | I2: 4 | J2: 3 | K2: 3 | L2: 2 | M2: 3 | N2: 2 | O2: 2 | P2: 4 | Q2: 4 | R2: 1 | S2: 5 | T2: 5 | U2: 3 | V2: 4 | W2: 3 | X2: 1 | Y2: 1 | Z2: Umowa cywilnoprawna | AA2: 2000 | AC2: =6-G2 -> 2 | AD2: =6-H2 -> 5 | AE2: =6-K2 -> 3 | AF2: =6-N2 -> 4 | AG2: =6-O2 -> 4 | AH2: =6-Q2 -> 2 | AI2: =6-R2 -> 5 | AJ2: =6-U2 -> 3 | AK2: =6-X2 -> 5 | AL2: =6-Y2 -> 5 | AN2: =AVERAGE(F2,P2,AE2,AJ2) -> 3 | AO2: =AVERAGE(L2,V2,AC2,AH2) -> 2.5 | AP2: =AVERAGE(H2,R2,AG2,AL2) -> 2.75 | AQ2: =AVERAGE(I2,S2,AF2,AK2) -> 4.5 | AR2: =AVERAGE(J2,T2,AG2,AL2) -> 4.25
A3: lep021q40n9ocwrns9lep0auifn6awaf | B3: 2025-12-23 09:46:03 | C3: Tak | D3: 1 | E3: Tak | F3: 3 | G3: 2 | H3: 2 | I3: 3 | J3: 3 | K3: 3 | L3: 4 | M3: 4 | N3: 4 | O3: 4 | P3: 4 | Q3: 2 | R3: 1 | S3: 2 | T3: 3 | U3: 1 | V3: 3 | W3: 3 | X3: 2 | Y3: 3 | Z3: Umowa o pracę | AA3: 4100 | AC3: =6-G3 -> 4 | AD3: =6-H3 -> 4 | AE3: =6-K3 -> 3 | AF3: =6-N3 -> 2 | AG3: =6-O3 -> 2 | AH3: =6-Q3 -> 4 | AI3: =6-R3 -> 5 | AJ3: =6-U3 -> 5 | AK3: =6-X3 -> 4 | AL3: =6-Y3 -> 3 | AN3: =AVERAGE(F3,P3,AE3,AJ3) -> 3.75 | AO3: =AVERAGE(L3,V3,AC3,AH3) -> 3.75 | AP3: =AVERAGE(H3,R3,AG3,AL3) -> 2 | AQ3: =AVERAGE(I3,S3,AF3,AK3) -> 2.75 | AR3: =AVERAGE(J3,T3,AG3,AL3) -> 2.75
A4: n13j7zr7jz37jwxf1ct0n13jmie4sp7f | B4: 2025-12-23 09:46:41 | C4: Tak | D4: 3 | E4: Tak | F4: 4 | G4: 2 | H4: 3 | I4: 5 | J4: 4 | K4: 3 | L4: 4 | M4: 1 | N4: 2 | O4: 2 | P4: 3 | Q4: 2 | R4: 2 | S4: 3 | T4: 5 | U4: 1 | V4: 4 | W4: 2 | X4: 1 | Y4: 3 | Z4: Umowa cywilnoprawna | AA4: 5600 | AC4: =6-G4 -> 4 | AD4: =6-H4 -> 3 | AE4: =6-K4 -> 3 | AF4: =6-N4 -> 4 | AG4: =6-O4 -> 4 | AH4: =6-Q4 -> 4 | AI4: =6-R4 -> 4 | AJ4: =6-U4 -> 5 | AK4: =6-X4 -> 5 | AL4: =6-Y4 -> 3 | AN4: =AVERAGE(F4,P4,AE4,AJ4) -> 3.75 | AO4: =AVERAGE(L4,V4,AC4,AH4) -> 4 | AP4: =AVERAGE(H4,R4,AG4,AL4) -> 3 | AQ4: =AVERAGE(I4,S4,AF4,AK4) -> 4.25 | AR4: =AVERAGE(J4,T4,AG4,AL4) -> 4
A5: ODqZMZp | B5: 2025-12-29 10:42:05 | C5: Tak | D5: 2 | E5: Tak | F5: 3 | G5: 3 | H5: 2 | I5: 2 | J5: 4 | K5: 4 | L5: 5 | M5: 1 | N5: 5 | O5: 2 | P5: 3 | Q5: 3 | R5: 1 | S5: 2 | T5: 3 | U5: 4 | V5: 4 | W5: 2 | X5: 4 | Y5: 1 | Z5: Umowa o pracę | AA5: 6500 | AC5: =6-G5 -> 3 | AD5: =6-H5 -> 4 | AE5: =6-K5 -> 2 | AF5: =6-N5 -> 1 | AG5: =6-O5 -> 4 | AH5: =6-Q5 -> 3 | AI5: =6-R5 -> 5 | AJ5: =6-U5 -> 2 | AK5: =6-X5 -> 2 | AL5: =6-Y5 -> 5 | AN5: =AVERAGE(F5,P5,AE5,AJ5) -> 2.5 | AO5: =AVERAGE(L5,V5,AC5,AH5) -> 3.75 | AP5: =AVERAGE(H5,R5,AG5,AL5) -> 3 | AQ5: =AVERAGE(I5,S5,AF5,AK5) -> 1.75 | AR5: =AVERAGE(J5,T5,AG5,AL5) -> 4
A6: nlchofm3ljohqlxnlcs1onfevjsvh5kg | B6: 2025-12-21 19:06:20 | C6: Tak | D6: 2 | E6: Tak | F6: 2 | G6: 3 | H6: 1 | I6: 2 | J6: 4 | K6: 4 | L6: 5 | M6: 2 | N6: 5 | O6: 2 | P6: 3 | Q6: 2 | R6: 1 | S6: 2 | T6: 2 | U6: 4 | V6: 4 | W6: 2 | X6: 3 | Y6: 1 | Z6: Umowa o pracę | AA6: 6500 | AC6: =6-G6 -> 3 | AD6: =6-H6 -> 5 | AE6: =6-K6 -> 2 | AF6: =6-N6 -> 1 | AG6: =6-O6 -> 4 | AH6: =6-Q6 -> 4 | AI6: =6-R6 -> 5 | AJ6: =6-U6 -> 2 | AK6: =6-X6 -> 3 | AL6: =6-Y6 -> 5 | AN6: =AVERAGE(F6,P6,AE6,AJ6) -> 2.25 | AO6: =AVERAGE(L6,V6,AC6,AH6) -> 4 | AP6: =AVERAGE(H6,R6,AG6,AL6) -> 2.75 | AQ6: =AVERAGE(I6,S6,AF6,AK6) -> 2 | AR6: =AVERAGE(J6,T6,AG6,AL6) -> 3.75
A7: q4QOvjg | B7: 2025-12-24 16:45:10 | C7: Tak | D7: 1.5 | E7: Tak | F7: 3 | G7: 4 | H7: 4 | I7: 4 | J7: 4 | K7: 3 | L7: 2 | M7: 4 | N7: 3 | O7: 1 | P7: 4 | Q7: 4 | R7: 5 | S7: 3 | T7: 4 | U7: 4 | V7: 3 | W7: 4 | X7: 2 | Y7: 1 | Z7: Umowa o pracę | AA7: 7000 | AC7: =6-G7 -> 2 | AD7: =6-H7 -> 2 | AE7: =6-K7 -> 3 | AF7: =6-N7 -> 3 | AG7: =6-O7 -> 5 | AH7: =6-Q7 -> 2 | AI7: =6-R7 -> 1 | AJ7: =6-U7 -> 2 | AK7: =6-X7 -> 4 | AL7: =6-Y7 -> 5 | AN7: =AVERAGE(F7,P7,AE7,AJ7) -> 3 | AO7: =AVERAGE(L7,V7,AC7,AH7) -> 2.25 | AP7: =AVERAGE(H7,R7,AG7,AL7) -> 4.75 | AQ7: =AVERAGE(I7,S7,AF7,AK7) -> 3.5 | AR7: =AVERAGE(J7,T7,AG7,AL7) -> 4.5
A8: tdvdrzi1hphy71tdvd5tcgiyt37a4ktg | B8: 2025-12-21 19:04:28 | C8: Tak | D8: 1 | E8: Tak | F8: 3 | G8: 2 | H8: 1 | I8: 5 | J8: 3 | K8: 4 | L8: 4 | M8: 3 | N8: 4 | O8: 5 | P8: 2 | Q8: 2 | R8: 2 | S8: 2 | T8: 5 | U8: 1 | V8: 4 | W8: 5 | X8: 5 | Y8: 1 | Z8: Umowa o pracę | AA8: 7000 | AC8: =6-G8 -> 4 | AD8: =6-H8 -> 5 | AE8: =6-K8 -> 2 | AF8: =6-N8 -> 2 | AG8: =6-O8 -> 1 | AH8: =6-Q8 -> 4 | AI8: =6-R8 -> 4 | AJ8: =6-U8 -> 5 | AK8: =6-X8 -> 1 | AL8: =6-Y8 -> 5 | AN8: =AVERAGE(F8,P8,AE8,AJ8) -> 3 | AO8: =AVERAGE(L8,V8,AC8,AH8) -> 4 | AP8: =AVERAGE(H8,R8,AG8,AL8) -> 2.25 | AQ8: =AVERAGE(I8,S8,AF8,AK8) -> 2.5 | AR8: =AVERAGE(J8,T8,AG8,AL8) -> 3.5
A9: Bzoa7DY | B9: 2025-12-22 09:12:36 | C9: Tak | D9: 4 | E9: Tak | F9: 5 | G9: 5 | H9: 2 | I9: 4 | J9: 5 | K9: 1 | L9: 3 | M9: 4 | N9: 5 | O9: 1 | P9: 5 | Q9: 2 | R9: 1 | S9: 3 | T9: 5 | U9: 1 | V9: 3 | W9: 4 | X9: 1 | Y9: 1 | Z9: Umowa o pracę | AA9: 8000 | AC9: =6-G9 -> 1 | AD9: =6-H9 -> 4 | AE9: =6-K9 -> 5 | AF9: =6-N9 -> 1 | AG9: =6-O9 -> 5 | AH9: =6-Q9 -> 4 | AI9: =6-R9 -> 5 | AJ9: =6-U9 -> 5 | AK9: =6-X9 -> 5 | AL9: =6-Y9 -> 5 | AN9: =AVERAGE(F9,P9,AE9,AJ9) -> 5 | AO9: =AVERAGE(L9,V9,AC9,AH9) -> 2.75 | AP9: =AVERAGE(H9,R9,AG9,AL9) -> 3.25 | AQ9: =AVERAGE(I9,S9,AF9,AK9) -> 3.25 | AR9: =AVERAGE(J9,T9,AG9,AL9) -> 5
A10: xXbY2OG | B10: 2025-12-23 09:44:40 | C10: Tak | D10: 22 | E10: Tak | F10: 5 | G10: 1 | H10: 4 | I10: 3 | J10: 4 | K10: 1 | L10: 5 | M10: 2 | N10: 4 | O10: 3 | P10: 5 | Q10: 1 | R10: 5 | S10: 5 | T10: 5 | U10: 2 | V10: 5 | W10: 4 | X10: 2 | Y10: 1 | Z10: Umowa o pracę | AA10: 9000 | AC10: =6-G10 -> 5 | AD10: =6-H10 -> 2 | AE10: =6-K10 -> 5 | AF10: =6-N10 -> 2 | AG10: =6-O10 -> 3 | AH10: =6-Q10 -> 5 | AI10: =6-R10 -> 1 | AJ10: =6-U10 -> 4 | AK10: =6-X10 -> 4 | AL10: =6-Y10 -> 5 | AN10: =AVERAGE(F10,P10,AE10,AJ10) -> 4.75 | AO10: =AVERAGE(L10,V10,AC10,AH10) -> 5 | AP10: =AVERAGE(H10,R10,AG10,AL10) -> 4.25 | AQ10: =AVERAGE(I10,S10,AF10,AK10) -> 3.5 | AR10: =AVERAGE(J10,T10,AG10,AL10) -> 4.25
A11: gD88rk4 | B11: 2026-01-07 08:32:59 | C11: Tak | D11: 7 | E11: Tak | F11: 3 | G11: 1 | H11: 3 | I11: 2 | J11: 4 | K11: 1 | L11: 4 | M11: 4 | N11: 5 | O11: 3 | P11: 1 | Q11: 1 | R11: 4 | S11: 1 | T11: 5 | U11: 2 | V11: 5 | W11: 4 | X11: 5 | Y11: 1 | Z11: B2B | AA11: 11000 | AC11: =6-G11 -> 5 | AD11: =6-H11 -> 3 | AE11: =6-K11 -> 5 | AF11: =6-N11 -> 1 | AG11: =6-O11 -> 3 | AH11: =6-Q11 -> 5 | AI11: =6-R11 -> 2 | AJ11: =6-U11 -> 4 | AK11: =6-X11 -> 1 | AL11: =6-Y11 -> 5 | AN11: =AVERAGE(F11,P11,AE11,AJ11) -> 3.25 | AO11: =AVERAGE(L11,V11,AC11,AH11) -> 4.75 | AP11: =AVERAGE(H11,R11,AG11,AL11) -> 3.75 | AQ11: =AVERAGE(I11,S11,AF11,AK11) -> 1.25 | AR11: =AVERAGE(J11,T11,AG11,AL11) -> 4.25
A12: 7gd906mis9qr0rmud7gd9087wbt48xaj | B12: 2025-12-21 19:46:56 | C12: Tak | D12: 4 | E12: Tak | F12: 4 | G12: 2 | H12: 1 | I12: 2 | J12: 4 | K12: 2 | L12: 5 | M12: 4 | N12: 5 | O12: 2 | P12: 3 | Q12: 1 | R12: 1 | S12: 3 | T12: 4 | U12: 2 | V12: 2 | W12: 4 | X12: 2 | Y12: 1 | Z12: Umowa o pracę | AA12: 11000 | AC12: =6-G12 -> 4 | AD12: =6-H12 -> 5 | AE12: =6-K12 -> 4 | AF12: =6-N12 -> 1 | AG12: =6-O12 -> 4 | AH12: =6-Q12 -> 5 | AI12: =6-R12 -> 5 | AJ12: =6-U12 -> 4 | AK12: =6-X12 -> 4 | AL12: =6-Y12 -> 5 | AN12: =AVERAGE(F12,P12,AE12,AJ12) -> 3.75 | AO12: =AVERAGE(L12,V12,AC12,AH12) -> 4 | AP12: =AVERAGE(H12,R12,AG12,AL12) -> 2.75 | AQ12: =AVERAGE(I12,S12,AF12,AK12) -> 2.5 | AR12: =AVERAGE(J12,T12,AG12,AL12) -> 4.25
A13: LZxZzNj | B13: 2025-12-21 20:38:53 | C13: Tak | D13: 5 | E13: Tak | F13: 3 | G13: 4 | H13: 4 | I13: 4 | J13: 4 | K13: 4 | L13: 3 | M13: 2 | N13: 4 | O13: 3 | P13: 2 | Q13: 4 | R13: 2 | S13: 2 | T13: 1 | U13: 5 | V13: 3 | W13: 2 | X13: 2 | Y13: 3 | Z13: Umowa o pracę | AA13: 12000 | AC13: =6-G13 -> 2 | AD13: =6-H13 -> 2 | AE13: =6-K13 -> 2 | AF13: =6-N13 -> 2 | AG13: =6-O13 -> 3 | AH13: =6-Q13 -> 2 | AI13: =6-R13 -> 4 | AJ13: =6-U13 -> 1 | AK13: =6-X13 -> 4 | AL13: =6-Y13 -> 3 | AN13: =AVERAGE(F13,P13,AE13,AJ13) -> 2 | AO13: =AVERAGE(L13,V13,AC13,AH13) -> 2.5 | AP13: =AVERAGE(H13,R13,AG13,AL13) -> 3 | AQ13: =AVERAGE(I13,S13,AF13,AK13) -> 3 | AR13: =AVERAGE(J13,T13,AG13,AL13) -> 2.75
... A39: obNBg8O | B39: 2025-12-24 07:46:55 | C39: Tak | D39: 22 | E39: Tak | F39: 1 | G39: 5 | H39: 5 | I39: 4 | J39: 2 | K39: 5 | L39: 3 | M39: 4 | N39: 5 | O39: 1 | P39: 1 | Q39: 5 | R39: 4 | S39: 2 | T39: 4 | U39: 5 | V39: 2 | W39: 2 | X39: 2 | Y39: 4 | Z39: B2B | AA39: 33000 | AC39: =6-G39 -> 1 | AD39: =6-H39 -> 1 | AE39: =6-K39 -> 1 | AF39: =6-N39 -> 1 | AG39: =6-O39 -> 5 | AH39: =6-Q39 -> 1 | AI39: =6-R39 -> 2 | AJ39: =6-U39 -> 1 | AK39: =6-X39 -> 4 | AL39: =6-Y39 -> 2 | AN39: =AVERAGE(F39,P39,AE39,AJ39) -> 1 | AO39: =AVERAGE(L39,V39,AC39,AH39) -> 1.75 | AP39: =AVERAGE(H39,R39,AG39,AL39) -> 4 | AQ39: =AVERAGE(I39,S39,AF39,AK39) -> 2.75 | AR39: =AVERAGE(J39,T39,AG39,AL39) -> 3.25
A42: OUTLIERS:
A43: ja89pK6 | B43: 2026-01-04 17:46:30 | C43: Tak | D43: 12 | E43: Tak | F43: 3 | G43: 2 | H43: 2 | I43: 2 | J43: 4 | K43: 4 | L43: 4 | M43: 2 | N43: 4 | O43: 2 | P43: 3 | Q43: 2 | R43: 3 | S43: 2 | T43: 3 | U43: 4 | V43: 3 | W43: 2 | X43: 3 | Y43: 2 | Z43: B2B | AA43: 57000 | AC43: =6-G43 -> 4 | AD43: =6-H43 -> 4 | AE43: =6-K43 -> 2 | AF43: =6-N43 -> 2 | AG43: =6-O43 -> 4 | AH43: =6-Q43 -> 4 | AI43: =6-R43 -> 3 | AJ43: =6-U43 -> 2 | AK43: =6-X43 -> 3 | AL43: =6-Y43 -> 4 | AN43: =AVERAGE(F43,P43,AE43,AJ43) -> 2.5 | AO43: =AVERAGE(L43,V43,AC43,AH43) -> 3.75 | AP43: =AVERAGE(H43,R43,AG43,AL43) -> 3.25 | AQ43: =AVERAGE(I43,S43,AF43,AK43) -> 2.25 | AR43: =AVERAGE(J43,T43,AG43,AL43) -> 3.75
A44: vG84DgX | B44: 2026-01-04 00:04:56 | C44: Tak | D44: 14 | E44: Tak | F44: 5 | G44: 4 | H44: 4 | I44: 3 | J44: 5 | K44: 5 | L44: 2 | M44: 3 | N44: 2 | O44: 1 | P44: 5 | Q44: 2 | R44: 5 | S44: 5 | T44: 5 | U44: 4 | V44: 4 | W44: 3 | X44: 5 | Y44: 1 | Z44: B2B | AA44: 57300 | AC44: =6-G44 -> 2 | AD44: =6-H44 -> 2 | AE44: =6-K44 -> 1 | AF44: =6-N44 -> 4 | AG44: =6-O44 -> 5 | AH44: =6-Q44 -> 4 | AI44: =6-R44 -> 1 | AJ44: =6-U44 -> 2 | AK44: =6-X44 -> 1 | AL44: =6-Y44 -> 5 | AN44: =AVERAGE(F44,P44,AE44,AJ44) -> 3.25 | AO44: =AVERAGE(L44,V44,AC44,AH44) -> 3 | AP44: =AVERAGE(H44,R44,AG44,AL44) -> 4.75 | AQ44: =AVERAGE(I44,S44,AF44,AK44) -> 3.25 | AR44: =AVERAGE(J44,T44,AG44,AL44) -> 5
A45: xdts23vofdriznskr9xdtsns2gzavjyi | B45: 2025-12-21 19:15:08 | C45: Tak | D45: 8 | E45: Tak | F45: 2 | G45: 2 | H45: 3 | I45: 4 | J45: 3 | K45: 4 | L45: 4 | M45: 2 | N45: 4 | O45: 2 | P45: 3 | Q45: 2 | R45: 2 | S45: 4 | T45: 4 | U45: 4 | V45: 4 | W45: 3 | X45: 2 | Y45: 2 | Z45: B2B | AA45: 75000 | AC45: =6-G45 -> 4 | AD45: =6-H45 -> 3 | AE45: =6-K45 -> 2 | AF45: =6-N45 -> 2 | AG45: =6-O45 -> 4 | AH45: =6-Q45 -> 4 | AI45: =6-R45 -> 4 | AJ45: =6-U45 -> 2 | AK45: =6-X45 -> 4 | AL45: =6-Y45 -> 4 | AN45: =AVERAGE(F45,P45,AE45,AJ45) -> 2.25 | AO45: =AVERAGE(L45,V45,AC45,AH45) -> 4 | AP45: =AVERAGE(H45,R45,AG45,AL45) -> 3.25 | AQ45: =AVERAGE(I45,S45,AF45,AK45) -> 3.5 | AR45: =AVERAGE(J45,T45,AG45,AL45) -> 3.75
A46: RGedkrQ | B46: 2025-12-22 14:35:03 | C46: Tak | D46: 8 | E46: Tak | F46: 4 | G46: 4 | H46: 5 | I46: 1 | J46: 3 | K46: 3 | L46: 2 | M46: 1 | N46: 5 | O46: 1 | P46: 4 | Q46: 4 | R46: 4 | S46: 2 | T46: 5 | U46: 2 | V46: 2 | W46: 2 | X46: 5 | Y46: 5 | Z46: B2B | AA46: 82700 | AC46: =6-G46 -> 2 | AD46: =6-H46 -> 1 | AE46: =6-K46 -> 3 | AF46: =6-N46 -> 1 | AG46: =6-O46 -> 5 | AH46: =6-Q46 -> 2 | AI46: =6-R46 -> 2 | AJ46: =6-U46 -> 4 | AK46: =6-X46 -> 1 | AL46: =6-Y46 -> 1 | AN46: =AVERAGE(F46,P46,AE46,AJ46) -> 3.75 | AO46: =AVERAGE(L46,V46,AC46,AH46) -> 2 | AP46: =AVERAGE(H46,R46,AG46,AL46) -> 3.75 | AQ46: =AVERAGE(I46,S46,AF46,AK46) -> 1.25 | AR46: =AVERAGE(J46,T46,AG46,AL46) -> 3.5
A47: zxBjqg8 | B47: 2025-12-22 09:24:27 | C47: Tak | D47: 12 | E47: Tak | F47: 3 | G47: 2 | H47: 3 | I47: 5 | J47: 4 | K47: 3 | L47: 4 | M47: 1 | N47: 3 | O47: 3 | P47: 3 | Q47: 4 | R47: 4 | S47: 4 | T47: 4 | U47: 2 | V47: 4 | W47: 3 | X47: 2 | Y47: 2 | Z47: B2B | AA47: 93000 | AC47: =6-G47 -> 4 | AD47: =6-H47 -> 3 | AE47: =6-K47 -> 3 | AF47: =6-N47 -> 3 | AG47: =6-O47 -> 3 | AH47: =6-Q47 -> 2 | AI47: =6-R47 -> 2 | AJ47: =6-U47 -> 4 | AK47: =6-X47 -> 4 | AL47: =6-Y47 -> 4 | AN47: =AVERAGE(F47,P47,AE47,AJ47) -> 3.25 | AO47: =AVERAGE(L47,V47,AC47,AH47) -> 3.5 | AP47: =AVERAGE(H47,R47,AG47,AL47) -> 3.5 | AQ47: =AVERAGE(I47,S47,AF47,AK47) -> 4 | AR47: =AVERAGE(J47,T47,AG47,AL47) -> 3.75
A48: 5B0QKKM | B48: 2025-12-27 22:37:02 | C48: Tak | D48: 16 | E48: Tak | F48: 2 | G48: 2 | H48: 4 | I48: 3 | J48: 3 | K48: 4 | L48: 4 | M48: 2 | N48: 3 | O48: 1 | P48: 2 | Q48: 2 | R48: 4 | S48: 3 | T48: 3 | U48: 5 | V48: 4 | W48: 3 | X48: 3 | Y48: 3 | Z48: B2B | AA48: 150000 | AC48: =6-G48 -> 4 | AD48: =6-H48 -> 2 | AE48: =6-K48 -> 2 | AF48: =6-N48 -> 3 | AG48: =6-O48 -> 5 | AH48: =6-Q48 -> 4 | AI48: =6-R48 -> 2 | AJ48: =6-U48 -> 1 | AK48: =6-X48 -> 3 | AL48: =6-Y48 -> 3 | AN48: =AVERAGE(F48,P48,AE48,AJ48) -> 1.75 | AO48: =AVERAGE(L48,V48,AC48,AH48) -> 4 | AP48: =AVERAGE(H48,R48,AG48,AL48) -> 4 | AQ48: =AVERAGE(I48,S48,AF48,AK48) -> 3 | AR48: =AVERAGE(J48,T48,AG48,AL48) -> 3.5
A52: Cecha | B52: Treść Pytania | C52: Typ Pytania
A53: Ekstrawersja | B53: Jestem duszą towarzystwa. | C53: WPROST
A54: Ekstrawersja | B54: Rozmawiam z wieloma różnymi ludźmi na przyjęciach. | C54: WPROST
A55: Ekstrawersja | B55: Trzymam się z boku. | C55: ODWRÓCONE
A56: Ekstrawersja | B56: Wśród nieznajomych jestem małomówny/a. | C56: ODWRÓCONE
A57: Ugodowość | B57: Jestem wyrozumiały/a dla uczuć innych ludzi. | C57: WPROST
A58: Ugodowość | B58: Znajduję czas dla innych. | C58: WPROST
A59: Ugodowość | B59: Niezbyt obchodzą mnie inni ludzie. | C59: ODWRÓCONE
A60: Ugodowość | B60: Nie interesują mnie problemy innych ludzi. | C60: ODWRÓCONE
A61: Sumienność | B61: Bez zwłoki wypełniam codzienne obowiązki. | C61: WPROST
A62: Sumienność | B62: Postępuję zgodnie z harmonogramem. | C62: WPROST
A63: Sumienność | B63: Zostawiam moje rzeczy gdzie popadnie. | C63: ODWRÓCONE
... A72: Intelekt (Otwartość) | B72: Nie mam zbyt bogatej wyobraźni. | C72: ODWRÓCONE

Sheet Analiza
A1: ='Twój kod jest świetny, a co z T'!A1 -> Submission ID | C1: ='Twój kod jest świetny, a co z T'!AA1 -> Zarobki | D1: CZY_B2B | E1: ='Twój kod jest świetny, a co z T'!D1 -> STAŻ PRACY | F1: ='Twój kod jest świetny, a co z T'!AN1 -> WYNIK_EKSTRAWERSJA | G1: ='Twój kod jest świetny, a co z T'!AO1 -> WYNIK_UGODOWOSC | H1: ='Twój kod jest świetny, a co z T'!AP1 -> WYNIK_SUMIENNOSC | I1: ='Twój kod jest świetny, a co z T'!AQ1 -> WYNIK_STABILNOSC_EMOCJONALNA | J1: ='Twój kod jest świetny, a co z T'!AR1 -> WYNIK_INTELEKT
A2: ='Twój kod jest świetny, a co z T'!A2 -> 9oxqs3ejiynzbyrf5915oz9oxqs2ztbl | C2: ='Twój kod jest świetny, a co z T'!AA2 -> 2000 | D2: =IF('Twój kod jest świetny, a co z T'!Z2 = "B2B", 1, 0) -> 0 | E2: ='Twój kod jest świetny, a co z T'!D2 -> 1 | F2: ='Twój kod jest świetny, a co z T'!AN2 -> 3 | G2: ='Twój kod jest świetny, a co z T'!AO2 -> 2.5 | H2: ='Twój kod jest świetny, a co z T'!AP2 -> 2.75 | I2: ='Twój kod jest świetny, a co z T'!AQ2 -> 4.5 | J2: ='Twój kod jest świetny, a co z T'!AR2 -> 4.25 | L2: Bez outliers:
A3: ='Twój kod jest świetny, a co z T'!A3 -> lep021q40n9ocwrns9lep0auifn6awaf | C3: ='Twój kod jest świetny, a co z T'!AA3 -> 4100 | D3: =IF('Twój kod jest świetny, a co z T'!Z3 = "B2B", 1, 0) -> 0 | E3: ='Twój kod jest świetny, a co z T'!D3 -> 1 | F3: ='Twój kod jest świetny, a co z T'!AN3 -> 3.75 | G3: ='Twój kod jest świetny, a co z T'!AO3 -> 3.75 | H3: ='Twój kod jest świetny, a co z T'!AP3 -> 2 | I3: ='Twój kod jest świetny, a co z T'!AQ3 -> 2.75 | J3: ='Twój kod jest świetny, a co z T'!AR3 -> 2.75 | L3: Regression
A4: ='Twój kod jest świetny, a co z T'!A4 -> n13j7zr7jz37jwxf1ct0n13jmie4sp7f | C4: ='Twój kod jest świetny, a co z T'!AA4 -> 5600 | D4: =IF('Twój kod jest świetny, a co z T'!Z4 = "B2B", 1, 0) -> 0 | E4: ='Twój kod jest świetny, a co z T'!D4 -> 3 | F4: ='Twój kod jest świetny, a co z T'!AN4 -> 3.75 | G4: ='Twój kod jest świetny, a co z T'!AO4 -> 4 | H4: ='Twój kod jest świetny, a co z T'!AP4 -> 3 | I4: ='Twój kod jest świetny, a co z T'!AQ4 -> 4.25 | J4: ='Twój kod jest świetny, a co z T'!AR4 -> 4 | L4: Regression Model | M4: Linear
A5: ='Twój kod jest świetny, a co z T'!A5 -> ODqZMZp | C5: ='Twój kod jest świetny, a co z T'!AA5 -> 6500 | D5: =IF('Twój kod jest świetny, a co z T'!Z5 = "B2B", 1, 0) -> 0 | E5: ='Twój kod jest świetny, a co z T'!D5 -> 2 | F5: ='Twój kod jest świetny, a co z T'!AN5 -> 2.5 | G5: ='Twój kod jest świetny, a co z T'!AO5 -> 3.75 | H5: ='Twój kod jest świetny, a co z T'!AP5 -> 3 | I5: ='Twój kod jest świetny, a co z T'!AQ5 -> 1.75 | J5: ='Twój kod jest świetny, a co z T'!AR5 -> 4
A6: ='Twój kod jest świetny, a co z T'!A6 -> nlchofm3ljohqlxnlcs1onfevjsvh5kg | C6: ='Twój kod jest świetny, a co z T'!AA6 -> 6500 | D6: =IF('Twój kod jest świetny, a co z T'!Z6 = "B2B", 1, 0) -> 0 | E6: ='Twój kod jest świetny, a co z T'!D6 -> 2 | F6: ='Twój kod jest świetny, a co z T'!AN6 -> 2.25 | G6: ='Twój kod jest świetny, a co z T'!AO6 -> 4 | H6: ='Twój kod jest świetny, a co z T'!AP6 -> 2.75 | I6: ='Twój kod jest świetny, a co z T'!AQ6 -> 2 | J6: ='Twój kod jest świetny, a co z T'!AR6 -> 3.75 | L6: LINEST raw output
A7: ='Twój kod jest świetny, a co z T'!A7 -> q4QOvjg | C7: ='Twój kod jest świetny, a co z T'!AA7 -> 7000 | D7: =IF('Twój kod jest świetny, a co z T'!Z7 = "B2B", 1, 0) -> 0 | E7: ='Twój kod jest świetny, a co z T'!D7 -> 1.5 | F7: ='Twój kod jest świetny, a co z T'!AN7 -> 3 | G7: ='Twój kod jest świetny, a co z T'!AO7 -> 2.25 | H7: ='Twój kod jest świetny, a co z T'!AP7 -> 4.75 | I7: ='Twój kod jest świetny, a co z T'!AQ7 -> 3.5 | J7: ='Twój kod jest świetny, a co z T'!AR7 -> 4.5 | L7: {=LINEST($C$2:$C$39 , $D$2:$J$39 , 1 , 1)} -> -501.38861 | M7: -1487.672 | N7: 1518.0967 | O7: -2392.7351 | P7: -406.27486 | Q7: 530.47576 | R7: 4622.8079 | S7: 18317.439
A8: ='Twój kod jest świetny, a co z T'!A8 -> tdvdrzi1hphy71tdvd5tcgiyt37a4ktg | C8: ='Twój kod jest świetny, a co z T'!AA8 -> 7000 | D8: =IF('Twój kod jest świetny, a co z T'!Z8 = "B2B", 1, 0) -> 0 | E8: ='Twój kod jest świetny, a co z T'!D8 -> 1 | F8: ='Twój kod jest świetny, a co z T'!AN8 -> 3 | G8: ='Twój kod jest świetny, a co z T'!AO8 -> 4 | H8: ='Twój kod jest świetny, a co z T'!AP8 -> 2.25 | I8: ='Twój kod jest świetny, a co z T'!AQ8 -> 2.5 | J8: ='Twój kod jest świetny, a co z T'!AR8 -> 3.5 | L8: 1341.7868 | M8: 855.79586 | N8: 1324.3387 | O8: 1164.7921 | P8: 926.42652 | Q8: 123.12508 | R8: 1491.707 | S8: 5773.0335
A9: ='Twój kod jest świetny, a co z T'!A9 -> Bzoa7DY | C9: ='Twój kod jest świetny, a co z T'!AA9 -> 8000 | D9: =IF('Twój kod jest świetny, a co z T'!Z9 = "B2B", 1, 0) -> 0 | E9: ='Twój kod jest świetny, a co z T'!D9 -> 4 | F9: ='Twój kod jest świetny, a co z T'!AN9 -> 5 | G9: ='Twój kod jest świetny, a co z T'!AO9 -> 2.75 | H9: ='Twój kod jest świetny, a co z T'!AP9 -> 3.25 | I9: ='Twój kod jest świetny, a co z T'!AQ9 -> 3.25 | J9: ='Twój kod jest świetny, a co z T'!AR9 -> 5 | L9: 0.69172836 | M9: 4153.2643 | N9: #N/A | O9: #N/A | P9: #N/A | Q9: #N/A | R9: #N/A | S9: #N/A
A10: ='Twój kod jest świetny, a co z T'!A10 -> xXbY2OG | C10: ='Twój kod jest świetny, a co z T'!AA10 -> 9000 | D10: =IF('Twój kod jest świetny, a co z T'!Z10 = "B2B", 1, 0) -> 0 | E10: ='Twój kod jest świetny, a co z T'!D10 -> 22 | F10: ='Twój kod jest świetny, a co z T'!AN10 -> 4.75 | G10: ='Twój kod jest świetny, a co z T'!AO10 -> 5 | H10: ='Twój kod jest świetny, a co z T'!AP10 -> 4.25 | I10: ='Twój kod jest świetny, a co z T'!AQ10 -> 3.5 | J10: ='Twój kod jest świetny, a co z T'!AR10 -> 4.25 | L10: 9.6166812 | M10: 30 | N10: #N/A | O10: #N/A | P10: #N/A | Q10: #N/A | R10: #N/A | S10: #N/A
A11: ='Twój kod jest świetny, a co z T'!A11 -> gD88rk4 | C11: ='Twój kod jest świetny, a co z T'!AA11 -> 11000 | D11: =IF('Twój kod jest świetny, a co z T'!Z11 = "B2B", 1, 0) -> 1 | E11: ='Twój kod jest świetny, a co z T'!D11 -> 7 | F11: ='Twój kod jest świetny, a co z T'!AN11 -> 3.25 | G11: ='Twój kod jest świetny, a co z T'!AO11 -> 4.75 | H11: ='Twój kod jest świetny, a co z T'!AP11 -> 3.75 | I11: ='Twój kod jest świetny, a co z T'!AQ11 -> 1.25 | J11: ='Twój kod jest świetny, a co z T'!AR11 -> 4.25 | L11: 1.1611876e+09 | M11: 5.1748814e+08 | N11: #N/A | O11: #N/A | P11: #N/A | Q11: #N/A | R11: #N/A | S11: #N/A
A12: ='Twój kod jest świetny, a co z T'!A12 -> 7gd906mis9qr0rmud7gd9087wbt48xaj | C12: ='Twój kod jest świetny, a co z T'!AA12 -> 11000 | D12: =IF('Twój kod jest świetny, a co z T'!Z12 = "B2B", 1, 0) -> 0 | E12: ='Twój kod jest świetny, a co z T'!D12 -> 4 | F12: ='Twój kod jest świetny, a co z T'!AN12 -> 3.75 | G12: ='Twój kod jest świetny, a co z T'!AO12 -> 4 | H12: ='Twój kod jest świetny, a co z T'!AP12 -> 2.75 | I12: ='Twój kod jest świetny, a co z T'!AQ12 -> 2.5 | J12: ='Twój kod jest świetny, a co z T'!AR12 -> 4.25
A13: ='Twój kod jest świetny, a co z T'!A13 -> LZxZzNj | C13: ='Twój kod jest świetny, a co z T'!AA13 -> 12000 | D13: =IF('Twój kod jest świetny, a co z T'!Z13 = "B2B", 1, 0) -> 0 | E13: ='Twój kod jest świetny, a co z T'!D13 -> 5 | F13: ='Twój kod jest świetny, a co z T'!AN13 -> 2 | G13: ='Twój kod jest świetny, a co z T'!AO13 -> 2.5 | H13: ='Twój kod jest świetny, a co z T'!AP13 -> 3 | I13: ='Twój kod jest świetny, a co z T'!AQ13 -> 3 | J13: ='Twój kod jest świetny, a co z T'!AR13 -> 2.75 | L13: Regression Statistics
A14: ='Twój kod jest świetny, a co z T'!A14 -> vG6GX6g | C14: ='Twój kod jest świetny, a co z T'!AA14 -> 13000 | D14: =IF('Twój kod jest świetny, a co z T'!Z14 = "B2B", 1, 0) -> 1 | E14: ='Twój kod jest świetny, a co z T'!D14 -> 5 | F14: ='Twój kod jest świetny, a co z T'!AN14 -> 2.25 | G14: ='Twój kod jest świetny, a co z T'!AO14 -> 3 | H14: ='Twój kod jest świetny, a co z T'!AP14 -> 3 | I14: ='Twój kod jest świetny, a co z T'!AQ14 -> 3.25 | J14: ='Twój kod jest świetny, a co z T'!AR14 -> 3.75 | L14: R^2 | M14: =$L$9 -> 0.69172836
A15: ='Twój kod jest świetny, a co z T'!A15 -> 680Ldje | C15: ='Twój kod jest świetny, a co z T'!AA15 -> 13500 | D15: =IF('Twój kod jest świetny, a co z T'!Z15 = "B2B", 1, 0) -> 1 | E15: ='Twój kod jest świetny, a co z T'!D15 -> 6 | F15: ='Twój kod jest świetny, a co z T'!AN15 -> 4 | G15: ='Twój kod jest świetny, a co z T'!AO15 -> 4.5 | H15: ='Twój kod jest świetny, a co z T'!AP15 -> 4 | I15: ='Twój kod jest świetny, a co z T'!AQ15 -> 2 | J15: ='Twój kod jest świetny, a co z T'!AR15 -> 3.75 | L15: Standard Error | M15: =$M$9 -> 4153.2643
A16: ='Twój kod jest świetny, a co z T'!A16 -> GxEKzkL | C16: ='Twój kod jest świetny, a co z T'!AA16 -> 13500 | D16: =IF('Twój kod jest świetny, a co z T'!Z16 = "B2B", 1, 0) -> 0 | E16: ='Twój kod jest świetny, a co z T'!D16 -> 9 | F16: ='Twój kod jest świetny, a co z T'!AN16 -> 2.75 | G16: ='Twój kod jest świetny, a co z T'!AO16 -> 4 | H16: ='Twój kod jest świetny, a co z T'!AP16 -> 3.75 | I16: ='Twój kod jest świetny, a co z T'!AQ16 -> 1.75 | J16: ='Twój kod jest świetny, a co z T'!AR16 -> 3 | L16: Count of X variables | M16: =7 -> 7
A17: ='Twój kod jest świetny, a co z T'!A17 -> GxEKJrL | C17: ='Twój kod jest świetny, a co z T'!AA17 -> 14000 | D17: =IF('Twój kod jest świetny, a co z T'!Z17 = "B2B", 1, 0) -> 0 | E17: ='Twój kod jest świetny, a co z T'!D17 -> 8 | F17: ='Twój kod jest świetny, a co z T'!AN17 -> 1 | G17: ='Twój kod jest świetny, a co z T'!AO17 -> 3.25 | H17: ='Twój kod jest świetny, a co z T'!AP17 -> 3.5 | I17: ='Twój kod jest świetny, a co z T'!AQ17 -> 1.25 | J17: ='Twój kod jest świetny, a co z T'!AR17 -> 4.25 | L17: Observations | M17: =38 -> 38
A18: ='Twój kod jest świetny, a co z T'!A18 -> aQJeaVW | C18: ='Twój kod jest świetny, a co z T'!AA18 -> 14000 | D18: =IF('Twój kod jest świetny, a co z T'!Z18 = "B2B", 1, 0) -> 1 | E18: ='Twój kod jest świetny, a co z T'!D18 -> 8 | F18: ='Twój kod jest świetny, a co z T'!AN18 -> 2.75 | G18: ='Twój kod jest świetny, a co z T'!AO18 -> 3.75 | H18: ='Twój kod jest świetny, a co z T'!AP18 -> 3.5 | I18: ='Twój kod jest świetny, a co z T'!AQ18 -> 4 | J18: ='Twój kod jest świetny, a co z T'!AR18 -> 4.5 | L18: Adjusted R^2 | M18: =1 - (1 - $L$9)*($M$17 - 1)/($M$17 - $M$16 - 1) -> 0.61979831
A19: ='Twój kod jest świetny, a co z T'!A19 -> b5R59Mo | C19: ='Twój kod jest świetny, a co z T'!AA19 -> 15000 | D19: =IF('Twój kod jest świetny, a co z T'!Z19 = "B2B", 1, 0) -> 1 | E19: ='Twój kod jest świetny, a co z T'!D19 -> 14 | F19: ='Twój kod jest świetny, a co z T'!AN19 -> 2.5 | G19: ='Twój kod jest świetny, a co z T'!AO19 -> 4 | H19: ='Twój kod jest świetny, a co z T'!AP19 -> 4 | I19: ='Twój kod jest świetny, a co z T'!AQ19 -> 2.25 | J19: ='Twój kod jest świetny, a co z T'!AR19 -> 4.25
A20: ='Twój kod jest świetny, a co z T'!A20 -> RGqJZEd | C20: ='Twój kod jest świetny, a co z T'!AA20 -> 15000 | D20: =IF('Twój kod jest świetny, a co z T'!Z20 = "B2B", 1, 0) -> 1 | E20: ='Twój kod jest świetny, a co z T'!D20 -> 5 | F20: ='Twój kod jest świetny, a co z T'!AN20 -> 1.75 | G20: ='Twój kod jest świetny, a co z T'!AO20 -> 3 | H20: ='Twój kod jest świetny, a co z T'!AP20 -> 3 | I20: ='Twój kod jest świetny, a co z T'!AQ20 -> 4 | J20: ='Twój kod jest świetny, a co z T'!AR20 -> 2.5 | L20: Analysis of Variance (ANOVA)
A21: ='Twój kod jest świetny, a co z T'!A21 -> RGe2DrJ | C21: ='Twój kod jest świetny, a co z T'!AA21 -> 15500 | D21: =IF('Twój kod jest świetny, a co z T'!Z21 = "B2B", 1, 0) -> 0 | E21: ='Twój kod jest świetny, a co z T'!D21 -> 22 | F21: ='Twój kod jest świetny, a co z T'!AN21 -> 3.5 | G21: ='Twój kod jest świetny, a co z T'!AO21 -> 4.5 | H21: ='Twój kod jest świetny, a co z T'!AP21 -> 3 | I21: ='Twój kod jest świetny, a co z T'!AQ21 -> 2 | J21: ='Twój kod jest świetny, a co z T'!AR21 -> 3.75 | M21: df | N21: SS | O21: MS | P21: F | Q21: Significance F
A22: ='Twój kod jest świetny, a co z T'!A22 -> Ekor0LL | C22: ='Twój kod jest świetny, a co z T'!AA22 -> 16000 | D22: =IF('Twój kod jest świetny, a co z T'!Z22 = "B2B", 1, 0) -> 1 | E22: ='Twój kod jest świetny, a co z T'!D22 -> 10 | F22: ='Twój kod jest świetny, a co z T'!AN22 -> 1.25 | G22: ='Twój kod jest świetny, a co z T'!AO22 -> 2.5 | H22: ='Twój kod jest świetny, a co z T'!AP22 -> 2.75 | I22: ='Twój kod jest świetny, a co z T'!AQ22 -> 2.25 | J22: ='Twój kod jest świetny, a co z T'!AR22 -> 4 | L22: Regression | M22: =$M$16 -> 7 | N22: =$L$11 -> 1.1611876e+09 | O22: =$L$11 / $M$22 -> 1.6588395e+08 | P22: =$L$10 -> 9.6166812 | Q22: =FDIST($L$10 , $M$22 , $M$10) -> 3.1755202e-06
A23: ='Twój kod jest świetny, a co z T'!A23 -> VL7LQ2a | C23: ='Twój kod jest świetny, a co z T'!AA23 -> 17000 | D23: =IF('Twój kod jest świetny, a co z T'!Z23 = "B2B", 1, 0) -> 1 | E23: ='Twój kod jest świetny, a co z T'!D23 -> 7 | F23: ='Twój kod jest świetny, a co z T'!AN23 -> 2.75 | G23: ='Twój kod jest świetny, a co z T'!AO23 -> 3 | H23: ='Twój kod jest świetny, a co z T'!AP23 -> 3.5 | I23: ='Twój kod jest świetny, a co z T'!AQ23 -> 3 | J23: ='Twój kod jest świetny, a co z T'!AR23 -> 3.5 | L23: Residual | M23: =$M$10 -> 30 | N23: =$M$11 -> 5.1748814e+08 | O23: =$M$11 / $M$10 -> 17249605
A24: ='Twój kod jest świetny, a co z T'!A24 -> f1fa38mavsz07f1fa32x8sisbcgg328g | C24: ='Twój kod jest świetny, a co z T'!AA24 -> 17000 | D24: =IF('Twój kod jest świetny, a co z T'!Z24 = "B2B", 1, 0) -> 1 | E24: ='Twój kod jest świetny, a co z T'!D24 -> 5 | F24: ='Twój kod jest świetny, a co z T'!AN24 -> 2.75 | G24: ='Twój kod jest świetny, a co z T'!AO24 -> 3.75 | H24: ='Twój kod jest świetny, a co z T'!AP24 -> 3 | I24: ='Twój kod jest świetny, a co z T'!AQ24 -> 2.5 | J24: ='Twój kod jest świetny, a co z T'!AR24 -> 3.75 | L24: Total | M24: =$M$22 + $M$10 -> 37 | N24: =$L$11 + $M$11 -> 1.6786758e+09
A25: ='Twój kod jest świetny, a co z T'!A25 -> ja4ZeWJ | C25: ='Twój kod jest świetny, a co z T'!AA25 -> 18000 | D25: =IF('Twój kod jest świetny, a co z T'!Z25 = "B2B", 1, 0) -> 0 | E25: ='Twój kod jest świetny, a co z T'!D25 -> 8 | F25: ='Twój kod jest świetny, a co z T'!AN25 -> 2 | G25: ='Twój kod jest świetny, a co z T'!AO25 -> 3.25 | H25: ='Twój kod jest świetny, a co z T'!AP25 -> 3.25 | I25: ='Twój kod jest świetny, a co z T'!AQ25 -> 3.75 | J25: ='Twój kod jest świetny, a co z T'!AR25 -> 3.5
A26: ='Twój kod jest świetny, a co z T'!A26 -> zxBNpPE | C26: ='Twój kod jest świetny, a co z T'!AA26 -> 18000 | D26: =IF('Twój kod jest świetny, a co z T'!Z26 = "B2B", 1, 0) -> 1 | E26: ='Twój kod jest świetny, a co z T'!D26 -> 10 | F26: ='Twój kod jest świetny, a co z T'!AN26 -> 3.25 | G26: ='Twój kod jest świetny, a co z T'!AO26 -> 4.25 | H26: ='Twój kod jest świetny, a co z T'!AP26 -> 4.75 | I26: ='Twój kod jest świetny, a co z T'!AQ26 -> 1.5 | J26: ='Twój kod jest świetny, a co z T'!AR26 -> 4.5 | L26: Confidence level | M26: 0.95
A27: ='Twój kod jest świetny, a co z T'!A27 -> QK9K0Dp | C27: ='Twój kod jest świetny, a co z T'!AA27 -> 19000 | D27: =IF('Twój kod jest świetny, a co z T'!Z27 = "B2B", 1, 0) -> 1 | E27: ='Twój kod jest świetny, a co z T'!D27 -> 10 | F27: ='Twój kod jest świetny, a co z T'!AN27 -> 3.25 | G27: ='Twój kod jest świetny, a co z T'!AO27 -> 3.75 | H27: ='Twój kod jest świetny, a co z T'!AP27 -> 4.75 | I27: ='Twój kod jest świetny, a co z T'!AQ27 -> 4 | J27: ='Twój kod jest świetny, a co z T'!AR27 -> 4.5
A28: ='Twój kod jest świetny, a co z T'!A28 -> 81Dz9BA | C28: ='Twój kod jest świetny, a co z T'!AA28 -> 20000 | D28: =IF('Twój kod jest świetny, a co z T'!Z28 = "B2B", 1, 0) -> 1 | E28: ='Twój kod jest świetny, a co z T'!D28 -> 8 | F28: ='Twój kod jest świetny, a co z T'!AN28 -> 3.5 | G28: ='Twój kod jest świetny, a co z T'!AO28 -> 4.25 | H28: ='Twój kod jest świetny, a co z T'!AP28 -> 3.25 | I28: ='Twój kod jest świetny, a co z T'!AQ28 -> 2.5 | J28: ='Twój kod jest świetny, a co z T'!AR28 -> 4.5 | M28: Coefficients | N28: Standard Error | O28: t-Statistic | P28: P-value | Q28: =_xlfn.CONCAT("Lower " , INT($M$26 * 100) , "%") -> Lower 95% | R28: =_xlfn.CONCAT("Upper " , INT($M$26 * 100) , "%") -> Upper 95%
A29: ='Twój kod jest świetny, a co z T'!A29 -> lb2rRG5 | C29: ='Twój kod jest świetny, a co z T'!AA29 -> 20000 | D29: =IF('Twój kod jest świetny, a co z T'!Z29 = "B2B", 1, 0) -> 1 | E29: ='Twój kod jest świetny, a co z T'!D29 -> 23 | F29: ='Twój kod jest świetny, a co z T'!AN29 -> 1.25 | G29: ='Twój kod jest świetny, a co z T'!AO29 -> 3 | H29: ='Twój kod jest świetny, a co z T'!AP29 -> 3.75 | I29: ='Twój kod jest świetny, a co z T'!AQ29 -> 3.25 | J29: ='Twój kod jest świetny, a co z T'!AR29 -> 3.75 | L29: ="Intercept" -> Intercept | M29: {=INDEX($L$7:$S$7, 1 , ROW($M$36)+1 - ROW())} -> 18317.439 | N29: {=INDEX($L$8:$S$8, 1 , ROW($N$36)+1 - ROW())} -> 5773.0335 | O29: {=$M$29:$M$36 / $N$29:$N$36} -> 3.1729313 | P29: {=TDIST(ABS($O$29:$O$36) , $M$10 , 2 )} -> 0.003472227 | Q29: {=$M$29:$M$36 - $N$29:$N$36 * TINV(1 - $M$26 , $M$10)} -> 6527.3315 | R29: {=$M$29:$M$36 + $N$29:$N$36 * TINV(1 - $M$26 , $M$10)} -> 30107.546
A30: ='Twój kod jest świetny, a co z T'!A30 -> b5R7LKe | C30: ='Twój kod jest świetny, a co z T'!AA30 -> 20000 | D30: =IF('Twój kod jest świetny, a co z T'!Z30 = "B2B", 1, 0) -> 0 | E30: ='Twój kod jest świetny, a co z T'!D30 -> 14 | F30: ='Twój kod jest świetny, a co z T'!AN30 -> 3.75 | G30: ='Twój kod jest świetny, a co z T'!AO30 -> 3.5 | H30: ='Twój kod jest świetny, a co z T'!AP30 -> 3.5 | I30: ='Twój kod jest świetny, a co z T'!AQ30 -> 2.5 | J30: ='Twój kod jest świetny, a co z T'!AR30 -> 4.5 | L30: =$D$1 -> CZY_B2B | M30: 4622.8079 | N30: 1491.707 | O30: 3.0990054 | P30: 0.0041950996 | Q30: 1576.3359 | R30: 7669.28
A31: ='Twój kod jest świetny, a co z T'!A31 -> LZxvKzp | C31: ='Twój kod jest świetny, a co z T'!AA31 -> 20000 | D31: =IF('Twój kod jest świetny, a co z T'!Z31 = "B2B", 1, 0) -> 1 | E31: ='Twój kod jest świetny, a co z T'!D31 -> 6 | F31: ='Twój kod jest świetny, a co z T'!AN31 -> 1 | G31: ='Twój kod jest świetny, a co z T'!AO31 -> 3.25 | H31: ='Twój kod jest świetny, a co z T'!AP31 -> 3 | I31: ='Twój kod jest świetny, a co z T'!AQ31 -> 1.5 | J31: ='Twój kod jest świetny, a co z T'!AR31 -> 3.25 | L31: =$E$1 -> STAŻ PRACY | M31: 530.47576 | N31: 123.12508 | O31: 4.3084299 | P31: 0.00016258827 | Q31: 279.02081 | R31: 781.93071
A32: ='Twój kod jest świetny, a co z T'!A32 -> EkVNWoA | C32: ='Twój kod jest świetny, a co z T'!AA32 -> 20000 | D32: =IF('Twój kod jest świetny, a co z T'!Z32 = "B2B", 1, 0) -> 1 | E32: ='Twój kod jest świetny, a co z T'!D32 -> 11 | F32: ='Twój kod jest świetny, a co z T'!AN32 -> 3.25 | G32: ='Twój kod jest świetny, a co z T'!AO32 -> 3.25 | H32: ='Twój kod jest świetny, a co z T'!AP32 -> 3.25 | I32: ='Twój kod jest świetny, a co z T'!AQ32 -> 2.25 | J32: ='Twój kod jest świetny, a co z T'!AR32 -> 4 | L32: =$F$1 -> WYNIK_EKSTRAWERSJA | M32: -406.27486 | N32: 926.42652 | O32: -0.43853976 | P32: 0.66413704 | Q32: -2298.2902 | R32: 1485.7405
A33: ='Twój kod jest świetny, a co z T'!A33 -> pbq90Pq | C33: ='Twój kod jest świetny, a co z T'!AA33 -> 20000 | D33: =IF('Twój kod jest świetny, a co z T'!Z33 = "B2B", 1, 0) -> 1 | E33: ='Twój kod jest świetny, a co z T'!D33 -> 15 | F33: ='Twój kod jest świetny, a co z T'!AN33 -> 4.5 | G33: ='Twój kod jest świetny, a co z T'!AO33 -> 3.75 | H33: ='Twój kod jest świetny, a co z T'!AP33 -> 3.25 | I33: ='Twój kod jest świetny, a co z T'!AQ33 -> 2.25 | J33: ='Twój kod jest świetny, a co z T'!AR33 -> 3.25 | L33: =$G$1 -> WYNIK_UGODOWOSC | M33: -2392.7351 | N33: 1164.7921 | O33: -2.0542164 | P33: 0.048757277 | Q33: -4771.5579 | R33: -13.912179
A34: ='Twój kod jest świetny, a co z T'!A34 -> poe8uuc88szbgk8kq90poe8uukjwxuy3 | C34: ='Twój kod jest świetny, a co z T'!AA34 -> 21300 | D34: =IF('Twój kod jest świetny, a co z T'!Z34 = "B2B", 1, 0) -> 1 | E34: ='Twój kod jest świetny, a co z T'!D34 -> 8 | F34: ='Twój kod jest świetny, a co z T'!AN34 -> 2 | G34: ='Twój kod jest świetny, a co z T'!AO34 -> 3 | H34: ='Twój kod jest świetny, a co z T'!AP34 -> 2.75 | I34: ='Twój kod jest świetny, a co z T'!AQ34 -> 2.25 | J34: ='Twój kod jest świetny, a co z T'!AR34 -> 2.5 | L34: =$H$1 -> WYNIK_SUMIENNOSC | M34: 1518.0967 | N34: 1324.3387 | O34: 1.1463055 | P34: 0.26073005 | Q34: -1186.5637 | R34: 4222.7572
A35: ='Twój kod jest świetny, a co z T'!A35 -> rj9dgyv | C35: ='Twój kod jest świetny, a co z T'!AA35 -> 22000 | D35: =IF('Twój kod jest świetny, a co z T'!Z35 = "B2B", 1, 0) -> 0 | E35: ='Twój kod jest świetny, a co z T'!D35 -> 9 | F35: ='Twój kod jest świetny, a co z T'!AN35 -> 2.5 | G35: ='Twój kod jest świetny, a co z T'!AO35 -> 3.25 | H35: ='Twój kod jest świetny, a co z T'!AP35 -> 4.25 | I35: ='Twój kod jest świetny, a co z T'!AQ35 -> 2 | J35: ='Twój kod jest świetny, a co z T'!AR35 -> 4.5 | L35: =$I$1 -> WYNIK_STABILNOSC_EMOCJONALNA | M35: -1487.672 | N35: 855.79586 | O35: -1.7383492 | P35: 0.092404752 | Q35: -3235.4404 | R35: 260.09627
A36: ='Twój kod jest świetny, a co z T'!A36 -> eqOEjgq | C36: ='Twój kod jest świetny, a co z T'!AA36 -> 22500 | D36: =IF('Twój kod jest świetny, a co z T'!Z36 = "B2B", 1, 0) -> 1 | E36: ='Twój kod jest świetny, a co z T'!D36 -> 8 | F36: ='Twój kod jest świetny, a co z T'!AN36 -> 3 | G36: ='Twój kod jest świetny, a co z T'!AO36 -> 3.75 | H36: ='Twój kod jest świetny, a co z T'!AP36 -> 4.25 | I36: ='Twój kod jest świetny, a co z T'!AQ36 -> 4 | J36: ='Twój kod jest świetny, a co z T'!AR36 -> 4.5 | L36: =$J$1 -> WYNIK_INTELEKT | M36: -501.38861 | N36: 1341.7868 | O36: -0.37367233 | P36: 0.71127594 | Q36: -3241.6829 | R36: 2238.9057
A37: ='Twój kod jest świetny, a co z T'!A37 -> gDP4PR4 | C37: ='Twój kod jest świetny, a co z T'!AA37 -> 23000 | D37: =IF('Twój kod jest świetny, a co z T'!Z37 = "B2B", 1, 0) -> 0 | E37: ='Twój kod jest świetny, a co z T'!D37 -> 19 | F37: ='Twój kod jest świetny, a co z T'!AN37 -> 3.5 | G37: ='Twój kod jest świetny, a co z T'!AO37 -> 4.5 | H37: ='Twój kod jest świetny, a co z T'!AP37 -> 3.5 | I37: ='Twój kod jest świetny, a co z T'!AQ37 -> 2 | J37: ='Twój kod jest świetny, a co z T'!AR37 -> 4.5
A38: ='Twój kod jest świetny, a co z T'!A38 -> 680x5QP | C38: ='Twój kod jest świetny, a co z T'!AA38 -> 28000 | D38: =IF('Twój kod jest świetny, a co z T'!Z38 = "B2B", 1, 0) -> 1 | E38: ='Twój kod jest świetny, a co z T'!D38 -> 10 | F38: ='Twój kod jest świetny, a co z T'!AN38 -> 1.25 | G38: ='Twój kod jest świetny, a co z T'!AO38 -> 1.5 | H38: ='Twój kod jest świetny, a co z T'!AP38 -> 3.75 | I38: ='Twój kod jest świetny, a co z T'!AQ38 -> 2 | J38: ='Twój kod jest świetny, a co z T'!AR38 -> 2.75 | L38: =$D$1 -> CZY_B2B | M38: =$E$1 -> STAŻ PRACY | N38: =$F$1 -> WYNIK_EKSTRAWERSJA | O38: =$G$1 -> WYNIK_UGODOWOSC | P38: =$H$1 -> WYNIK_SUMIENNOSC | Q38: =$I$1 -> WYNIK_STABILNOSC_EMOCJONALNA | R38: =$J$1 -> WYNIK_INTELEKT | S38: Predicted Y | T38: =$C$1 -> Zarobki | U38: Residual
A39: ='Twój kod jest świetny, a co z T'!A39 -> obNBg8O | C39: ='Twój kod jest świetny, a co z T'!AA39 -> 33000 | D39: =IF('Twój kod jest świetny, a co z T'!Z39 = "B2B", 1, 0) -> 1 | E39: ='Twój kod jest świetny, a co z T'!D39 -> 22 | F39: ='Twój kod jest świetny, a co z T'!AN39 -> 1 | G39: ='Twój kod jest świetny, a co z T'!AO39 -> 1.75 | H39: ='Twój kod jest świetny, a co z T'!AP39 -> 4 | I39: ='Twój kod jest świetny, a co z T'!AQ39 -> 2.75 | J39: ='Twój kod jest świetny, a co z T'!AR39 -> 3.25 | L39: {=$D$2:$J$39} -> 0 | M39: 1 | N39: 3 | O39: 2.5 | P39: 2.75 | Q39: 4.5 | R39: 4.25 | S39: {=MMULT($L$39:$R$76 , $M$30:$M$36) + $M$29} -> 6996.5925 | T39: {=$C$2:$C$39} -> 2000 | U39: {=$T$39:$T$76 - $S$39:$S$76} -> -4996.5925
L40: 0 | M40: 1 | N40: 3.75 | O40: 3.75 | P40: 2 | Q40: 2.75 | R40: 2.75 | S40: 5917.904 | T40: 4100 | U40: -1817.904
...
